Traceback (most recent call last):
  File "/opt/conda/envs/MetaChat_test/lib/python3.9/site-packages/jupyter_cache/executors/utils.py", line 58, in single_nb_execution
    executenb(
  File "/opt/conda/envs/MetaChat_test/lib/python3.9/site-packages/nbclient/client.py", line 1314, in execute
    return NotebookClient(nb=nb, resources=resources, km=km, **kwargs).execute()
  File "/opt/conda/envs/MetaChat_test/lib/python3.9/site-packages/jupyter_core/utils/__init__.py", line 165, in wrapped
    return loop.run_until_complete(inner)
  File "/opt/conda/envs/MetaChat_test/lib/python3.9/asyncio/base_events.py", line 647, in run_until_complete
    return future.result()
  File "/opt/conda/envs/MetaChat_test/lib/python3.9/site-packages/nbclient/client.py", line 709, in async_execute
    await self.async_execute_cell(
  File "/opt/conda/envs/MetaChat_test/lib/python3.9/site-packages/nbclient/client.py", line 1062, in async_execute_cell
    await self._check_raise_for_error(cell, cell_index, exec_reply)
  File "/opt/conda/envs/MetaChat_test/lib/python3.9/site-packages/nbclient/client.py", line 918, in _check_raise_for_error
    raise CellExecutionError.from_cell_and_msg(cell, exec_reply_content)
nbclient.exceptions.CellExecutionError: An error occurred while executing the following cell:
------------------
mc.pp.compute_longRangeDistance(adata = adata,
                                database_name = "msdb_example1",
                                df_MetaSen = df_MetaSen,
                                LRC_name = ["type1"],
                                dis_thr = 10,
                                k_neighb = 5,
                                LRC_strength = 4,
                                plot = True,
                                spot_size = 1)
------------------


[0;31m---------------------------------------------------------------------------[0m
[0;31mAttributeError[0m                            Traceback (most recent call last)
Cell [0;32mIn[8], line 1[0m
[0;32m----> 1[0m [43mmc[49m[38;5;241;43m.[39;49m[43mpp[49m[38;5;241;43m.[39;49m[43mcompute_longRangeDistance[49m(adata [38;5;241m=[39m adata,
[1;32m      2[0m                                 database_name [38;5;241m=[39m [38;5;124m"[39m[38;5;124mmsdb_example1[39m[38;5;124m"[39m,
[1;32m      3[0m                                 df_MetaSen [38;5;241m=[39m df_MetaSen,
[1;32m      4[0m                                 LRC_name [38;5;241m=[39m [[38;5;124m"[39m[38;5;124mtype1[39m[38;5;124m"[39m],
[1;32m      5[0m                                 dis_thr [38;5;241m=[39m [38;5;241m10[39m,
[1;32m      6[0m                                 k_neighb [38;5;241m=[39m [38;5;241m5[39m,
[1;32m      7[0m                                 LRC_strength [38;5;241m=[39m [38;5;241m4[39m,
[1;32m      8[0m                                 plot [38;5;241m=[39m [38;5;28;01mTrue[39;00m,
[1;32m      9[0m                                 spot_size [38;5;241m=[39m [38;5;241m1[39m)

[0;31mAttributeError[0m: module 'metachat.preprocessing' has no attribute 'compute_longRangeDistance'

